Workbook

Sheet INICIO
A1: DESCRIPTION | B1: PLACEHOLDER | C1: VALUE
A2: Número de informe | B2: numero_id | C2: 7
A3: Fecha de emisión de informe (hoy) | B3: fecha_emision | C3: =TODAY() -> 46306
A4: Fecha de ayer | B4: fecha_48 | C4: =$C$3-1 -> 46305
A5: Fecha de anteayer | B5: fecha_72 | C5: =$C$3-2 -> 46304
A6: Fecha pronostico 24 horas | B6: fecha_pronos_24 | C6: =$C$3+1 -> 46307
A7: Fecha pronostico 48 horas | B7: fecha_pronos_48 | C7: =$C$3+2 -> 46308
A8: Fecha pronostico 72 horas | B8: fecha_pronos_72 | C8: =$C$3+3 -> 46309
A9: Titulo informe | B9: titulo | C9: El río Uruguay registra niveles estables en Bella Unión y Salto.

Sheet YI
A1: DESCRIPTION | B1: PLACEHOLDER | C1: VALUE
A2: Último dato en Sarandí del Yí | B2: nivel_actual_sarandi | C2: 2.08
A3: anterior dato en Sarandí del Yí (1 hora) | B3: nivel_pasado_sarandi | C3: 2.12
A4: tasa de incremento (cm/hora) | B4: tasa_sarandi | C4: =IF((C2-C3)>=0,ROUND((C2-C3)*100,0),"")
A5: tendencia (sube, baja o permanece) | B5: tendencia_sarandi | C5: =IF(C4=0,"Permanece",IF(C4="","Baja","Sube")) -> Baja
A6: último dato en Polanco de Yí | B6: nivel_actual_polanco | C6: 4.55
A7: anterior dato en Polanco de Yí (1 hora) | B7: nivel_pasado_polanco | C7: 4.51
A8: nivel pico anterior en Polanco de Yí | B8: nivel_pico_anterior_polanco | C8: -
A9: tasa de incremento (cm/hora) | B9: tasa_polanco | C9: =IF((C6-C7)>=0,ROUND((C6-C7)*100,0),"") -> 4
A10: tendencia (sube, baja o permanece) | B10: tendencia_polanco | C10: =IF(C9=0,"Permanece",IF(C9="","Baja","Sube")) -> Sube
A11: último dato en Durazno Puente Viejo | B11: nivel_actual_viejo | C11: 4.51
A12: anterior dato en Durazno Puente Viejo (1 hora) | B12: nivel_pasado_viejo | C12: 4.56
A13: nivel pico anterior en Puente Viejo | B13: nivel_pico_anterior_viejo
A14: tasa de incremento (cm/hora) | B14: tasa_viejo | C14: =IF((C11-C12)>=0,ROUND((C11-C12)*100,0),"")
A15: tendencia (sube, baja o permanece) | B15: tendencia_viejo | C15: =IF(C14=0,"Permanece",IF(C14="","Baja","Sube")) -> Baja
A16: último dato en Durazno Puente Nuevo | B16: nivel_actual_nuevo | C16: 2.31
A17: anterior dato en Durazno Puente Nuevo (1 hora) | B17: nivel_pasado_nuevo | C17: 2.32
A18: nivel pico anterior en Puente Viejo | B18: nivel_pico_anterior_catalan
A19: tasa de incremento (cm/hora) | B19: tasa_nuevo | C19: =IF((C16-C17)>=0,ROUND((C16-C17)*100,0),"")
A20: tendencia (sube, baja o permanece) | B20: tendencia_nuevo | C20: =IF(C19=0,"Permanece",IF(C19="","Baja","Sube")) -> Baja
A21: Acumulado diario | B21: pobs_24_yi | C21: 0
A22: Acumulado 3 días | B22: pobs_48_yi | C22: 0
A23: Acumulado semanal | B23: pobs_72_yi | C23: 49
A24: Lluvia pronosticada próximas 24 horas | B24: psim_24_yi | C24: 0
A25: Lluvia pronosticada próximas 72 horas | B25: psim_48_yi | C25: 3
A26: Lluvia pronosticada próximas Semana | B26: psim_72_yi | C26: 9
A27: Pronostico hidrologico en Sarandí del Yí | B27: pronos_sarandi | C27: -
A28: fecha ocurrencia nivel máximo en Sarandí del Yí | B28: fecha_sarandi | C28: -
A29: Pronostico hidrológico en Polanco del Yí | B29: pronos_polanco | C29: -
A30: fecha ocurrencia nivel máximo en Polanco del Yí | B30: fecha_polanco | C30: -
A31: Pronostico hidrológico en Durazno Puente Viejo | B31: pronos_viejo | C31: -
A32: fecha ocurrencia nivel máximo en Durazno Puente Viejo | B32: fecha_viejo | C32: -
A33: Pronostico hidrologico en Durazno Puente Nuevo | B33: pronos_nuevo | C33: -
A34: fecha ocurrencia nivel máximo en Durazno Puente Nuevo | B34: fecha_nuevo | C34: -
A35: Pronóstico hidrológico (no mayor a 1000 palabras) | B35: diagnostico_yi | C35: Durante las últimas horas se ha observado el descenso del nivel del río Yí en la ciudad de Durazno. Sin embargo, el nivel actual reportado por la UTE muestra que aun el nivel del río está por encima de la cota de seguridad.
A36: Recomendación al SINAE | B36: recomendacion_yi | C36: Mantener la vigilancia y el monitoreo en niveles de ríos y arroyos. Infórmese por fuentes oficiales

Sheet CUAREIM
A1: DESCRIPTION | B1: PLACEHOLDER | C1: VALUE
A2: Último dato en Catalan Grande | B2: nivel_actual_catalan | C2: 4.41
A3: anterior dato en Catalan Grande (1 hora) | B3: nivel_pasado_catalan | C3: 4.45
A4: nivel pico anterior en Catalan Grande | B4: nivel_pico_anterior_catalan | C4: -
A5: tasa de incremento (cm/hora) | B5: tasa_catalan | C5: =IF((C2-C3)>=0,ROUND((C2-C3)*100,0),"")
A6: tendencia (sube, baja o permanece) | B6: tendencia_catalan | C6: =IF(C5=0,"Permanece",IF(C5="","Baja","Sube")) -> Baja
A7: último dato en Cuareim Río | B7: nivel_actual_cuareim | C7: 2.84
A8: anterior dato en Cuareim Río (1 hora) | B8: nivel_pasado_cuareim | C8: 2.86
A9: nivel pico anterior en Cuareim Río | B9: nivel_pico_anterior_cuareim | C9: -
A10: tasa de incremento (cm/hora) | B10: tasa_cuareim | C10: =IF((C7-C8)>=0,ROUND((C7-C8)*100,0),"")
A11: tendencia (sube, baja o permanece) | B11: tendencia_cuareim | C11: =IF(C10=0,"Permanece",IF(C10="","Baja","Sube")) -> Baja
A12: último dato en Artigas | B12: nivel_actual_artigas | C12: 3.9
A13: anterior dato en Artigas (1 hora) | B13: nivel_pasado_artigas | C13: 3.92
A14: nivel pico anterior en Artigas | B14: nivel_pico_anterior_artigas | C14: -
A15: tasa de incremento (cm/hora) | B15: tasa_artigas | C15: =IF((C12-C13)>=0,ROUND((C12-C13)*100,0),"")
A16: tendencia (sube, baja o permanece) | B16: tendencia_artigas | C16: =IF(C15=0,"Permanece",IF(C15="","Baja","Sube")) -> Baja
A17: Acumulado diario | B17: pobs_24_cuareim | C17: 0
A18: Acumulado 3 días | B18: pobs_48_cuareim | C18: 10
A19: Acumulado semanal | B19: pobs_72_cuareim | C19: 51
A20: Lluvia pronosticada próximas 24 horas | B20: psim_24_cuareim | C20: 1
A21: Lluvia pronosticada próximas 72 horas | B21: psim_48_cuareim | C21: 2
A22: Lluvia pronosticada próximas Semana | B22: psim_72_cuareim | C22: 7
A23: Pronostico hidrologico en Catalan Grande | B23: pronos_catalan | C23: -
A24: fecha ocurrencia nivel máximo en Catalan Grande | B24: fecha_catalan | C24: -
A25: Pronostico hidrológico en Cuareim Río | B25: pronos_cuareim | C25: -
A26: fecha ocurrencia nivel máximo en Cuareim Río | B26: fecha_cuareim | C26: -
A27: Pronostico hidrológico en Artigas | B27: pronos_artigas | C27: Entre 8.50 a 9.60 metros
A28: fecha ocurrencia nivel máximo en Artigas | B28: fecha_artigas | C28: Entre 21 y 22 agosto
A29: Pronóstico hidrológico (no mayor a 1000 palabras) | B29: diagnostico_cuareim | C29: En los últimos dias se ha registrado un ascenso del nivel del río Cuareim en Artigas que estuvo levemente por debajo de la cota de aviso (8.00 metros) definido para la ciudad de Artigas. Debido a las precipitaciones previstas para los próximos dias, se espera que el nivel del río se mantenga alto y con posibilidad de generar un segundo pico o crecida que podria superar la cota de aviso pero estaria por debajo de la cota de seguridad (10.20 m), en función de la precipitación pronosticada.
A30: Recomendación al SINAE | B30: recomendacion_cuareim | C30: Estar atentos a la posiblidad de generarse inundaciones en los primeros equipamientos colectivos expuesto de la localidad y pérdida de conectividad terrestre por crecidas

Sheet SANTALUCIA
A1: DESCRIPTION | B1: PLACEHOLDER | C1: VALUE
A2: Último dato en Fray Marcos | B2: nivel_actual_fmarcos | C2: 0.72
A3: anterior dato en Fray Marcos (1 hora) | B3: nivel_pasado_fmarcos | C3: 0.74
A4: nivel pico anterior en Fray Marcos | B4: nivel_pico_anterior_fmarcos | C4: -
A5: tasa de incremento (cm/hora) | B5: tasa_fmarcos | C5: =IF((C2-C3)>=0,ROUND((C2-C3)*100,0),"")
A6: tendencia (sube, baja o permanece) | B6: tendencia_fmarcos | C6: =IF(C5=0,"Permanece",IF(C5="","Baja","Sube")) -> Baja
A7: último dato en Paso Pache | B7: nivel_actual_pache | C7: 0.63
A8: anterior dato en Paso Pache (1 hora) | B8: nivel_pasado_pache | C8: 0.65
A9: nivel pico anterior en Paso Pache | B9: nivel_pico_anterior_pache | C9: -
A10: tasa de incremento (cm/hora) | B10: tasa_pache | C10: =IF((C7-C8)>=0,ROUND((C7-C8)*100,0),"")
A11: tendencia (sube, baja o permanece) | B11: tendencia_pache | C11: =IF(C10=0,"Permanece",IF(C10="","Baja","Sube")) -> Baja
A12: último dato en Santa Lucia Ruta 11 | B12: nivel_actual_lucia | C12: 4.35
A13: anterior dato en Santa Lucia Ruta 11 (1 hora) | B13: nivel_pasado_lucia | C13: 4.4
A14: nivel pico anterior en Santa Lucia Ruta 11 | B14: nivel_pico_anterior_lucia
A15: tasa de incremento (cm/hora) | B15: tasa_lucia | C15: =IF((C12-C13)>=0,ROUND((C12-C13)*100,0),"")
A16: tendencia (sube, baja o permanece) | B16: tendencia_lucia | C16: =IF(C15=0,"Permanece",IF(C15="","Baja","Sube")) -> Baja
A17: último dato en Florida Ruta 5 | B17: nivel_actual_florida | C17: 2.96
A18: anterior dato en Florida Ruta 5 (1 hora) | B18: nivel_pasado_florida | C18: 2.98
A19: nivel pico anterior en Florida Ruta 5 | B19: nivel_pico_anterior_florida
A20: tasa de incremento (cm/hora) | B20: tasa_florida | C20: =IFERROR(ROUND(ABS(C17-C18)*100,0),"-") -> 2
A21: tendencia (sube, baja o permanece) | B21: tendencia_florida | C21: =IFERROR(IF(C20=0,"Permanece",IF(SIGN(C20)=1,"Sube","Baja")),"-") -> Sube
A22: Acumulado diario | B22: pobs_24_santalucia | C22: 0
A23: Acumulado 3 días | B23: pobs_48_santalucia | C23: 1
A24: Acumulado semanal | B24: pobs_72_santalucia | C24: 27
A25: Lluvia pronosticada próximas 24 horas | B25: psim_24_santalucia | C25: 1
A26: Lluvia pronosticada próximas 72 horas | B26: psim_48_santalucia | C26: 3
A27: Lluvia pronosticada próximas Semana | B27: psim_72_santalucia | C27: 7
A28: Pronostico hidrologico en San Ramón | B28: pronos_ramon
A29: fecha ocurrencia nivel máximo en San Ramón | B29: fecha_ramon
A30: Pronostico hidrologico en Fray Marcos | B30: pronos_fraymarcos
A31: fecha ocurrencia nivel máximo en Fray Marcos | B31: fecha_fraymarcos
A32: Pronostico hidrológico en Paso Pache | B32: pronos_pache | C32: Entre 4.41 a 5.87 metros
A33: fecha ocurrencia nivel máximo en Paso Pache | B33: fecha_pache | C33: Entre 20 y 22 agosto
A34: Pronóstico hidrológico en Canelones | B34: pronos_canelones | C34: -
A35: fecha de ocurrencia nivel máximo en Canelones | B35: fecha_canelones | C35: -
A36: Pronostico hidrológico en Santa Lucia Ruta 11 | B36: pronos_santalucia | C36: Entre 6.5 a 8.0 metros
A37: fecha ocurrencia nivel máximo en Santa Lucia Ruta 11 | B37: fecha_santalucia | C37: Entre 21 y 22 agosto
A38: Pronostico hidrologico en Florida Ruta 5 | B38: pronos_florida
A39: fecha ocurrencia nivel máximo en Florida Ruta 5 | B39: fecha_florida
A40: Pronóstico hidrológico (no mayor a 1000 palabras) | B40: diagnostico_santalucia | C40: En las últimas horas el río Santa Lucía alcanzó un nivel máximo de 6,00 metros en la estación Fray Marcos. A partir de este comportamiento, se prevé que en los próximos días el nivel en Santa Lucía (Ruta 11) se sitúe entre los 6,50 y 8,00 metros. De alcanzarse estos valores, se superaría la cota de aviso (6,80 m), manteniéndose por debajo de la cota de seguridad (9,00 m). Debido a las precipitaciones pronosticadas, no se descarta que el río permanezca crecido ni la ocurrencia de un segundo repunte de mayor magnitud. Se actualizará la información una vez registrados los acumulados de lluvia en la cuenca.
...

Sheet SANJOSE
A1: DESCRIPTION | B1: PLACEHOLDER | C1: VALUE
A2: último dato en Picada de Varela | B2: nivel_actual_varela | C2: 3.61
A3: anterior dato en Picada de Varela (1 hora) | B3: nivel_pasado_varela | C3: 3.68
A4: nivel pico anterior en Picada de Varela | B4: nivel_pico_anterior_varela | C4: -
A5: tasa de incremento (cm/hora) | B5: tasa_varela | C5: =IF((C2-C3)>=0,ROUND((C2-C3)*100,0),"")
A6: tendencia (sube, baja o permanece) | B6: tendencia_varela | C6: =IF(C5=0,"Permanece",IF(C5="","Baja","Sube")) -> Baja
A7: Acumulado diario | B7: pobs_24_jose | C7: 0
A8: Acumulado 3 días | B8: pobs_48_jose | C8: 1
A9: Acumulado semanal | B9: pobs_72_jose | C9: 43
A10: Lluvia pronosticada próximas 24 horas | B10: psim_24_jose | C10: 1
A11: Lluvia pronosticada próximas 72 horas | B11: psim_48_jose | C11: 3
A12: Lluvia pronosticada próximas Semana | B12: psim_72_jose | C12: 9
A13: Pronóstico hidrológico en Picada de Varela | B13: pronos_varela | C13: Menor a 2.0 metros
A14: fecha de ocurrencia nivel máximo en Picada de Varela | B14: fecha_varela | C14: 22 julio
A15: Pronóstico hidrológico (no mayor a 1000 palabras) | B15: diagnostico_jose | C15: Se observa un incremento de nivel del río San José el cual tiene posibilidad de aproximarse a la cota de aviso (3,32 metros) en las próximas horas. Debido a las precipitaciones pronosticadas, no se descarta que el río permanezca crecido en los próximos días. La probabilidad de llegar a cota de seguridad (7.40 m) es baja pero se actualizará información si se tiene un cambio en las condiciones hidrológicas
A16: Recomendación al SINAE | B16: recomendacion_jose | C16: Estar atentos a los pronósticos meteorológicos que realiza el INUMET y a los próximos eventos de lluvia que se registren en la cuenca.

Sheet URUGUAY
A1: DESCRIPTION | B1: PLACEHOLDER | C1: VALUE
A2: Último dato en Paso de los Libres | B2: nivel_actual_libres | C2: 9.12
A3: anterior dato en Paso de los Libres (1 hora) | B3: nivel_pasado_libres | C3: 9.12
A4: nivel pico anterior en Paso de los Libres | B4: nivel_pico_anterior_libres | C4: -
A5: tasa de incremento (cm/hora) | B5: tasa_libres | C5: =IF((C2-C3)>=0,ROUND((C2-C3)*100,0),"") -> 0
A6: tendencia (sube, baja o permanece) | B6: tendencia_libres | C6: =IF(C5=0,"Permanece",IF(C5="","Baja","Sube")) -> Permanece
A7: último dato en Bella Unión | B7: nivel_actual_bella | C7: 6.74
A8: anterior dato en Bella Unión(1 hora) | B8: nivel_pasado_bella | C8: 6.74
A9: nivel pico anterior en Bella Unión | B9: nivel_pico_anterior_bella | C9: -
A10: tasa de incremento (cm/hora) | B10: tasa_bella | C10: =IF((C7-C8)>=0,ROUND((C7-C8)*100,0),"") -> 0
A11: tendencia (sube, baja o permanece) | B11: tendencia_bella | C11: =IF(C10=0,"Permanece",IF(C10="","Baja","Sube")) -> Permanece
A12: último dato en Salto | B12: nivel_actual_salto | C12: 11.84
A13: anterior dato en Salto (1 hora) | B13: nivel_pasado_salto | C13: 11.84
A14: nivel pico anterior en Salto | B14: nivel_pico_anterior_salto | C14: -
A15: tasa de incremento (cm/hora) | B15: tasa_salto | C15: =IF((C12-C13)>=0,ROUND((C12-C13)*100,0),"") -> 0
A16: tendencia (sube, baja o permanece) | B16: tendencia_salto | C16: =IF(C15=0,"Permanece",IF(C15="","Baja","Sube")) -> Permanece
A17: último dato en Paysandú | B17: nivel_actual_ps | C17: 6.27
A18: anterior dato en Paysandú(1 hora) | B18: nivel_pasado_ps | C18: 6.27
A19: nivel pico anterior en Paysandú | B19: nivel_pico_anterior_ps | C19: -
A20: tasa de incremento (cm/hora) | B20: tasa_ps | C20: =IF((C17-C18)>=0,ROUND((C17-C18)*100,0),"") -> 0
A21: tendencia (sube, baja o permanece) | B21: tendencia_ps | C21: =IF(C20=0,"Permanece",IF(C20="","Baja","Sube")) -> Permanece
A22: último dato en Fray Bentos | B22: nivel_actual_bentos | C22: 3.02
A23: anterior dato en Fray Bentos(1 hora) | B23: nivel_pasado_bentos | C23: 3.02
A24: nivel pico anterior en Fray Bentos | B24: nivel_pico_anterior_bentos | C24: -
A25: tasa de incremento (cm/hora) | B25: tasa_bentos | C25: =IF((C22-C23)>=0,ROUND((C22-C23)*100,0),"") -> 0
A26: tendencia (sube, baja o permanece) | B26: tendencia_bentos | C26: =IF(C25=0,"Permanece",IF(C25="","Baja","Sube")) -> Permanece
A27: Caudal erogado previsto en CTM-Salto Grande | B27: q_erogado_ctm | C27: 18500 y 18000
A28: Pronostico hidrologico en Bella Unión | B28: pronos_bellaunion | C28: Alrededor de 6,90 m
A29: fecha ocurrencia nivel máximo en Bella Unión | B29: fecha_bellaunion | C29: 12 de octubre
A30: Pronostico hidrológico en Salto | B30: pronos_salto | C30: Menor a 12,10 m
A31: fecha ocurrencia nivel máximo en Salto | B31: fecha_salto | C31: 12 de octubre
A32: Pronostico hidrológico en Paysandú | B32: pronos_paysandu | C32: Alrededor de 6,40 m
A33: fecha ocurrencia nivel máximo en Paysandú | B33: fecha_paysandu | C33: 12 de octubre
A34: Pronostico hidrológico en Fray Bentos | B34: pronos_fraybentos | C34: Menor a 3,50 metros
A35: fecha ocurrencia nivel máximo en Fray Bentos | B35: fecha_fraybentos | C35: 13-14 de octubre
A36: Pronóstico hidrológico (no mayor a 1000 palabras) | B36: diagnostico_uruguay | C36: Durante las últimas horas se ha observado una tendencia estable del río Uruguay en el tramo Paso de los Libres (Argentina) y Bella Unión. Sin embargo, se espera para los próximos días un repunte del río Uruguay debido a las lluvias registradas en la parte alta de la cuenca. Para las próximas horas se espera que el Río Uruguay en Bella Unión se encuentre estable y por debajo de los 6,90 metros. En Salto, de acuerdo a la CTM de Salto Grande, se espera que el nivel del río sea menor a 12,10 metros. En Paysandú, se espera que el nivel del río se mantenga por debajo de los 6,40 metros. En Fray Bentos se espera que el nivel del río se mantenga inferior de 3,50 metros para los próximos 2 a 3 días.
A37: Recomendación al SINAE | B37: recomendacion_uruguay | C37: Se recomienda mantener las medidas de respuesta y el seguimiento de la evolución de los niveles del río Uruguay, principalmente en Bella Unión y Paysandú, donde se han superado las cotas de seguridad. Asimismo, se recomienda mantener la vigilancia ante posibles nuevos incrementos de los niveles durante los próximos días.

Sheet NEGRO
A1: DESCRIPTION | B1: PLACEHOLDER | C1: VALUE
A2: Último dato en San Gregorio de Polanco | B2: nivel_actual_gregorio | C2: 9.99
A3: anterior dato en San Gregorio de Polanco (1 hora) | B3: nivel_pasado_gregorio | C3: 9.99
A4: nivel pico anterior en San Gregorio de Polanco | B4: nivel_pico_anterior_gregorio | C4: -
A5: tasa de incremento (cm/hora) | B5: tasa_gregorio | C5: =IF((C2-C3)>=0,ROUND((C2-C3)*100,0),"") -> 0
A6: tendencia (sube, baja o permanece) | B6: tendencia_gregorio | C6: =IF(C5=0,"Permanece",IF(C5="","Baja","Sube")) -> Permanece
A7: último dato en Puente Mercedes | B7: nivel_actual_mercedes | C7: 3.02
A8: anterior dato en Mercedes (1 hora) | B8: nivel_pasado_mercedes | C8: 3.01
A9: nivel pico anterior en Mercedes | B9: nivel_pico_anterior_mercedes | C9: -
A10: tasa de incremento (cm/hora) | B10: tasa_mercedes | C10: =IF((C7-C8)>=0,ROUND((C7-C8)*100,0),"") -> 1
A11: tendencia (sube, baja o permanece) | B11: tendencia_mercedes | C11: =IF(C10=0,"Permanece",IF(C10="","Baja","Sube")) -> Sube
A12: Caudal erogado previsto en Rincón del Bonete | B12: q_erogado_bonete | C12: 1606 y 1065
A13: Caudal erogado previsto en Constitución | B13: q_erogado_palmar | C13: 1781 y 1280
A14: Pronostico hidrológico en San Gregorio de Polanco | B14: pronos_gregorio | C14: Entre 10.72 y 11.68 metros
A15: fecha ocurrencia nivel máximo en San Gregorio de Polanco | B15: fecha_gregorio | C15: 26 de agosto
A16: Pronostico hidrologico en Puente Mercedes | B16: pronos_mercedes | C16: Menor a 5.97 metros
A17: fecha ocurrencia nivel máximo en Puente Mercedes | B17: fecha_mercedes | C17: 21 de agosto
A18: Pronóstico hidrológico (no mayor a 1000 palabras) | B18: diagnostico_negro | C18: En las últimas horas se ha observado semi-estacionario el nivel del río Negro en Mercedes
A19: Recomendación al SINAE | B19: recomendacion_negro | C19: Estar preparados a la posibilidad de aproximarse a la cota de seguridad en la ciudad de Mercedes

Sheet OLIMAR
A1: DESCRIPTION | B1: PLACEHOLDER | C1: VALUE
A2: último dato en Treinta y Tres | B2: nivel_actual_treintatres | C2: 2.06
A3: anterior dato en Treinta y Tres (1 hora) | B3: nivel_pasado_treintatres | C3: 2.05
A4: nivel pico anterior en Treinta y Tres | B4: nivel_pico_anterior_treintatres | C4: -
A5: tasa de incremento (cm/hora) | B5: tasa_treintatres | C5: =IF((C2-C3)>=0,ROUND((C2-C3)*100,0),"") -> 1
A6: tendencia (sube, baja o permanece) | B6: tendencia_treintatres | C6: =IF(C5=0,"Permanece",IF(C5="","Baja","Sube")) -> Sube
A7: Acumulado diario | B7: pobs_24_olimar | C7: 0
A8: Acumulado 3 días | B8: pobs_48_olimar | C8: 1
A9: Acumulado semanal | B9: pobs_72_olimar | C9: 26
A10: Lluvia pronosticada próximas 24 horas | B10: psim_24_olimar | C10: 1
A11: Lluvia pronosticada próximas 72 horas | B11: psim_48_olimar | C11: 2
A12: Lluvia pronosticada próximas Semana | B12: psim_72_olimar | C12: 8
A13: Pronostico hidrologico en Treinta y Tres | B13: pronos_treintatres | C13: Entre 5.70 a 6.70 metros
A14: fecha ocurrencia nivel máximo en Treinta y Tres | B14: fecha_treintatres | C14: Entre 21 y 22 de julio
A15: Pronóstico hidrológico (no mayor a 1000 palabras) | B15: diagnostico_olimar | C15: Ayer el nivel del río Olimar Grande superó la cota de seguridad (7,0 metros) en la ciudad de Treinta y Tres. Actualmente se mantiene en niveles elevados, con previsión de estabilizarse y alcanzar su pico máximo en las próximas horas. Debido a las precipitaciones pronosticadas y a los niveles de saturación de los suelos, se espera que el caudal del río permanezca alto hasta el 23 de agosto de 2026, prolongando la afectación en las áreas anegadas.
A16: Recomendación al SINAE | B16: recomendacion_olimar | C16: Estar atentos y preparados a la posibilidad de un segundo evento de precipitación que podrian mantener las zonas inundadas en los próximos dias

Sheet Tablas
A1: Recomendaciones al SINAE | C1: Pronóstico hidrologico
A2: Mantener la vigilancia y el monitoreo en niveles de ríos y arroyos. Infórmese por fuentes oficiales | C2: Condicion | D2: P diara max. | E2: P ac. 72h | F2: En las últimas horas se registraron precipitaciones de fuerte intensidad en la cuenca (promedio 62 mm) del río Cuareim.
A3: Estar atentos a la posiblidad de generarse inundaciones en los primeros equipamientos colectivos expuesto de la localidad y pérdida de conectividad terrestre por crecidas | C3: > | D3: 70 | E3: 200 | F3: En las últimas horas se registraron importantes acumulados de precipitación en la cuenca del | I3: , donde en las últimas 72 horas se acumularon | J3: mm y con un máximo de | K3: mm/día.
A4: Estar preparados ante la posibilidad de generarse inundaciones en zona de vivienda de uso permanente ubicada en la trama urbana. | C4: > | D4: 30 | E4: 100 | F4: En las últimas horas se registraron acumulados de precipitación moderados en la cuenca del
A5: Tomar acción en realizar evacuaciones debido a la posibilidad de generarse inundaciones que afecten viviendas, infraestructura sensible y equipamientos urbanos | F5: En las últimas horas se registraron bajos acumulados de precipitación en la cuenca del
E7: Tendencia | F7: El nivel del río Cuareim en la ciudad de Artigas se mantiene actualmente en un nivel constante.
E8: Sube | F8: Actualmente, el nivel del | I8: está en ascenso | J8: en la ciudad de
E9: Permanece | I9: se mantiene constante | J9: en las ciudades de
E10: Baja | I10: está en descenso
C12: Ultimo N | D12: Condicion | E12: Pronostico N | F12: Considerando las lluvias y los niveles registrados en las estaciones de monitoreo, existe la posibilidad de nuevos incrementos de nivel que mantendrían las zonas de vivienda inundadas en los próximos días.
D13: > | F13: Considerando las lluvias pronosticadas y los niveles registrados en las estaciones de monitoreo, | I13: existe la posibilidad de nuevos incrementos de nivel en los próximos días.
D14: = | I14: no se prevén nuevos incrementos de nivel en los próximos días.
D15: < | I15: se prevé que el nivel descienda en los próximos días.
C17: Ultimo N | D17: Condicion | E17: Pronostico N | F17: Por el momento, la probabilidad de un incremento superior al registrado los días anteriores (10.60 metros) es baja pero no se puede descartar en su totalidad.
F18: Existe una alta probabilidad de que el nivel supere al máximo registrado los días anteriores ( | I18: metros).
F19: Existe una baja probabilidad de que el nivel supere al máximo registrado los días anteriores ( | I19: metros), pero no se puede descartar en su totalidad.
C22: Cuenca | D22: Río | E22: Ciudad | F22: Frase1 | I22: Frase2 | J22: Frase3 | K22: Frase4 | L22: Frase completa
C23: Yí | D23: río Yí | E23: Durazno | F23: =_xlfn.CONCAT(IF(OR(MAX(YI!C21:C23)>$D$3,SUM(YI!C21:C23)>$E$3),$F$3,IF(OR(MAX(YI!C21:C23)>$D$4,SUM(YI!C21:C23)>$E$4),$F$4,$F$5)),D23,$I$3,SUM(YI!C21:C23),$J$3,MAX(YI!C21:C23),$K$3) -> En las últimas horas se registraron acumulados de precipitación moderados en la cuenca del río Yí, donde en las últimas 72 horas se acumularon 49 mm y con un máximo de 49 mm/día. | I23: =_xlfn.CONCAT($F$8,D23,IF(YI!C15=$E$8,$I$8,IF(YI!C15=$E$9,$I$9,$I$10)),$J$8,E23,". ") -> Actualmente, el nivel del río Yí está en descenso en la ciudad de Durazno. | J23: =_xlfn.CONCAT(F13,IF(YI!C31>YI!C11,I13, IF(YI!C31=YI!C11,I14, I15))) -> Considerando las lluvias pronosticadas y los niveles registrados en las estaciones de monitoreo, existe la posibilidad de nuevos incrementos de nivel en los próximos días. | K23: =IF(YI!C13="-","",IF(YI!C31>YI!C13,_xlfn.CONCAT(F18,YI!C13,I18),_xlfn.CONCAT(F19,YI!C13,I19))) -> Existe una alta probabilidad de que el nivel supere al máximo registrado los días anteriores ( metros). | L23: =+_xlfn.CONCAT(F23," ",I23, " ",J23," ",K23) -> En las últimas horas se registraron acumulados de precipitación moderados en la cuenca del río Yí, donde en las últimas 72 horas se acumularon 49 mm y con un máximo de 49 mm/día. Actualmente, el nivel del río Yí está en descenso en la ciudad de Durazno. Considerando las lluvias pronosticadas y los niveles registrados en las estaciones de monitoreo, existe la posibilidad de nuevos incrementos de nivel en los próximos días. Existe una alta probabilidad de que el nivel supere al máximo registrado los días anteriores ( metros).
C24: Cuareim | D24: río Cuareim | E24: Artigas | F24: =_xlfn.CONCAT(IF(OR(MAX(CUAREIM!C17:C19)>$D$3,SUM(CUAREIM!C17:C19)>$E$3),$F$3,IF(OR(MAX(CUAREIM!C17:C19)>$D$4,SUM(CUAREIM!C17:C19)>$E$4),$F$4,$F$5)),D24,$I$3,SUM(CUAREIM!C17:C19),$J$3,MAX(CUAREIM!C17:C19),$K$3) -> En las últimas horas se registraron acumulados de precipitación moderados en la cuenca del río Cuareim, donde en las últimas 72 horas se acumularon 61 mm y con un máximo de 51 mm/día. | I24: =_xlfn.CONCAT($F$8,D24,IF(CUAREIM!C16=$E$8,$I$8,IF(CUAREIM!C16=$E$9,$I$9,$I$10)),$J$8,E24,". ") -> Actualmente, el nivel del río Cuareim está en descenso en la ciudad de Artigas. | J24: =_xlfn.CONCAT(F13,IF(CUAREIM!C27>CUAREIM!C12,I13, IF(CUAREIM!C27=CUAREIM!C12,I14, I15))) -> Considerando las lluvias pronosticadas y los niveles registrados en las estaciones de monitoreo, existe la posibilidad de nuevos incrementos de nivel en los próximos días. | K24: =IF(CUAREIM!C14="-","",IF(CUAREIM!C27>CUAREIM!C14,_xlfn.CONCAT(F18,CUAREIM!C14,I18),_xlfn.CONCAT(F19,CUAREIM!C14,I19))) | L24: =+_xlfn.CONCAT(F24," ",I24, " ",J24," ",K24) -> En las últimas horas se registraron acumulados de precipitación moderados en la cuenca del río Cuareim, donde en las últimas 72 horas se acumularon 61 mm y con un máximo de 51 mm/día. Actualmente, el nivel del río Cuareim está en descenso en la ciudad de Artigas. Considerando las lluvias pronosticadas y los niveles registrados en las estaciones de monitoreo, existe la posibilidad de nuevos incrementos de nivel en los próximos días.
C25: Santa Lucía | D25: río Santa Lucía | E25: Santa Lucía | F25: =_xlfn.CONCAT(IF(OR(MAX(SANTALUCIA!C22:C24)>$D$3,SUM(SANTALUCIA!C22:C24)>$E$3),$F$3,IF(OR(MAX(SANTALUCIA!C22:C24)>$D$4,SUM(SANTALUCIA!C22:C24)>$E$4),$F$4,$F$5)),D25,$I$3,SUM(SANTALUCIA!C22:C24),$J$3,MAX(SANTALUCIA!C22:C24),$K$3) -> En las últimas horas se registraron bajos acumulados de precipitación en la cuenca del río Santa Lucía, donde en las últimas 72 horas se acumularon 28 mm y con un máximo de 27 mm/día. | I25: =_xlfn.CONCAT($F$8,D25,IF(SANTALUCIA!C16=$E$8,$I$8,IF(SANTALUCIA!C16=$E$9,$I$9,$I$10)),$J$8,E25,". ") -> Actualmente, el nivel del río Santa Lucía está en descenso en la ciudad de Santa Lucía. | J25: =_xlfn.CONCAT(F13,IF(SANTALUCIA!C36>SANTALUCIA!C12,I13, IF(SANTALUCIA!C36=SANTALUCIA!C12,I14, I15))) -> Considerando las lluvias pronosticadas y los niveles registrados en las estaciones de monitoreo, existe la posibilidad de nuevos incrementos de nivel en los próximos días. | K25: =IF(SANTALUCIA!C14="-","",IF(SANTALUCIA!C36>SANTALUCIA!C14,_xlfn.CONCAT(F18,SANTALUCIA!C14,I18),_xlfn.CONCAT(F19,SANTALUCIA!C14,I19))) -> Existe una alta probabilidad de que el nivel supere al máximo registrado los días anteriores ( metros). | L25: =+_xlfn.CONCAT(F25," ",I25, " ",J25," ",K25) -> En las últimas horas se registraron bajos acumulados de precipitación en la cuenca del río Santa Lucía, donde en las últimas 72 horas se acumularon 28 mm y con un máximo de 27 mm/día. Actualmente, el nivel del río Santa Lucía está en descenso en la ciudad de Santa Lucía. Considerando las lluvias pronosticadas y los niveles registrados en las estaciones de monitoreo, existe la posibilidad de nuevos incrementos de nivel en los próximos días. Existe una alta probabilidad de que el nivel supere al máximo registrado los días anteriores ( metros).
C26: Uruguay | D26: río Uruguay | E26: Bella Unión | F26: =_xlfn.CONCAT(IF(OR(MAX(URUGUAY!#REF!)>$D$3,SUM(URUGUAY!#REF!)>$E$3),$F$3,IF(OR(MAX(URUGUAY!#REF!)>$D$4,SUM(URUGUAY!#REF!)>$E$4),$F$4,$F$5)),D26,$I$3,SUM(URUGUAY!#REF!),$J$3,MAX(URUGUAY!#REF!),$K$3) -> #REF! | I26: =IF(AND(URUGUAY!$C$11=$E$8,URUGUAY!$C$16=$E$8,URUGUAY!$C$21=$E$8,URUGUAY!$C$26=$E$8),_xlfn.CONCAT($F$8,$D$26,$I$8,$J$9," ",E26,", ",E27,", ",E28," y ",Tablas!E29,"."),IF(AND(URUGUAY!$C$11=$E$9,URUGUAY!$C$16=$E$9,URUGUAY!$C$21=$E$9,URUGUAY!$C$26=$E$9),_xlfn.CONCAT($F$8,$D$26,$I$9,$J$9," ",E26,", ",E27,", ",E28," y ",E29,"."),IF(AND(URUGUAY!$C$11=$E$10,URUGUAY!$C$16=$E$10,URUGUAY!$C$21=$E$10,URUGUAY!$C$26=$E$10),_xlfn.CONCAT($F$8,$D$26,$I$10,$J$9," ",E26,", ",E27,", ",E28," y ",E29,"."),_xlfn.CONCAT($F$8,D26,I27,I28,I29)))) -> Actualmente, el nivel del río Uruguay se mantiene constante en las ciudades de Bella Unión, Salto, Paysandú y Fray Bentos. | J26: =_xlfn.CONCAT(F13,IF(AND(URUGUAY!C28>URUGUAY!C7, URUGUAY!C30>URUGUAY!C12, URUGUAY!C32>URUGUAY!C17, URUGUAY!C34>URUGUAY!C22),I13, IF(AND(URUGUAY!C28=URUGUAY!C7, URUGUAY!C30=URUGUAY!C12, URUGUAY!C32=URUGUAY!C17, URUGUAY!C34=URUGUAY!C22),I14, I15))) -> Considerando las lluvias pronosticadas y los niveles registrados en las estaciones de monitoreo, existe la posibilidad de nuevos incrementos de nivel en los próximos días. | K26: =IF(AND(URUGUAY!C9="-", URUGUAY!C14="-", URUGUAY!C19="-", URUGUAY!C24="-"),"",IF(OR(URUGUAY!C28>URUGUAY!C9, URUGUAY!C30>URUGUAY!C14, URUGUAY!C32>URUGUAY!C19,URUGUAY!C34>URUGUAY!C24),_xlfn.CONCAT(F18,IF(URUGUAY!C9<>"-",_xlfn.CONCAT(URUGUAY!C9,"m en ",E26," "),""), IF(URUGUAY!C14<>"-",_xlfn.CONCAT(URUGUAY!C14, "m en ",E27," "),""),IF(URUGUAY!C19<>"-",_xlfn.CONCAT(URUGUAY!C19,"m en ",E28," "),""),IF(URUGUAY!C24<>"-",_xlfn.CONCAT(URUGUAY!C24,"m en ",E29),""),")."),_xlfn.CONCAT(F19,IF(URUGUAY!C9<>"-",_xlfn.CONCAT(URUGUAY!C9,"m en ",E26," "),""), IF(URUGUAY!C14<>"-",_xlfn.CONCAT(URUGUAY!C14, "m en ",E27," "),""),IF(URUGUAY!C19<>"-",_xlfn.CONCAT(URUGUAY!C19,"m en ",E28," "),""),IF(URUGUAY!C24<>"-",_xlfn.CONCAT(URUGUAY!C24,"m en ",E29),""),", pero no se puede descartar en su totalidad."))) -> Existe una alta probabilidad de que el nivel supere al máximo registrado los días anteriores ( -m en Paysandú ). | L26: =+_xlfn.CONCAT(F26," ",I26, " ",J26," ",K26) -> #REF!
E27: Salto | G27: =SUM(URUGUAY!$C$11=Tablas!E8, URUGUAY!$C$16=Tablas!E8,URUGUAY!$C$21=Tablas!E8,URUGUAY!$C$26=Tablas!E8) -> 0 | H27: =_xlfn.CONCAT(IF(URUGUAY!$C$11=Tablas!E8,_xlfn.CONCAT(" ",$E$26,),""),IF(URUGUAY!$C$16=Tablas!E8,_xlfn.CONCAT(" ",$E$27),""),IF(URUGUAY!$C$21=Tablas!E8,_xlfn.CONCAT(" ",$E$28),""),IF(URUGUAY!$C$26=Tablas!E8,_xlfn.CONCAT(" ",$E$29),"")) | I27: =_xlfn.CONCAT(I8,IF(G27>1,$J$9,$J$8),H27, IF(G27=4,".", ";")) -> está en ascenso en la ciudad de ;
E28: Paysandú | G28: =SUM(URUGUAY!$C$11=Tablas!E9, URUGUAY!$C$16=Tablas!E9,URUGUAY!$C$21=Tablas!E9,URUGUAY!$C$26=Tablas!E9) -> 4 | H28: =_xlfn.CONCAT(IF(URUGUAY!$C$11=Tablas!E9,_xlfn.CONCAT(" ",$E$26),""),IF(URUGUAY!$C$16=Tablas!E9,_xlfn.CONCAT(" ",$E$27),""),IF(URUGUAY!$C$21=Tablas!E9,_xlfn.CONCAT(" ",$E$28),""),IF(URUGUAY!$C$26=Tablas!E9,_xlfn.CONCAT(" ",$E$29),"")) -> Bella Unión Salto Paysandú Fray Bentos | I28: =_xlfn.CONCAT(I9,IF(G28>1,$J$9,$J$8),H28, IF((G27+G28)=4,".", ";")) -> se mantiene constante en las ciudades de Bella Unión Salto Paysandú Fray Bentos.
E29: Fray Bentos | G29: =SUM(URUGUAY!$C$11=Tablas!E10, URUGUAY!$C$16=Tablas!E10,URUGUAY!$C$21=Tablas!E10,URUGUAY!$C$26=Tablas!E10) -> 0 | H29: =_xlfn.CONCAT(IF(URUGUAY!$C$11=Tablas!E10,_xlfn.CONCAT(" ",$E$26),""),IF(URUGUAY!$C$16=Tablas!E10,_xlfn.CONCAT(" ",$E$27),""),IF(URUGUAY!$C$21=Tablas!E10,_xlfn.CONCAT(" ",$E$28),""),IF(URUGUAY!$C$26=Tablas!E10,_xlfn.CONCAT(" ",$E$29),"")) | I29: =_xlfn.CONCAT(I10,IF(G29>1,$J$9,$J$8),H29, ".") -> está en descenso en la ciudad de .
C30: Río Negro | D30: Río Negro | E30: Mercedes | F30: =_xlfn.CONCAT(IF(OR(MAX(NEGRO!#REF!)>$D$3,SUM(NEGRO!#REF!)>$E$3),$F$3,IF(OR(MAX(NEGRO!#REF!)>$D$4,SUM(NEGRO!#REF!)>$E$4),$F$4,$F$5)),D30,$I$3,SUM(NEGRO!#REF!),$J$3,MAX(NEGRO!#REF!),$K$3) -> #REF! | I30: =_xlfn.CONCAT($F$8,D30,IF(NEGRO!C11=$E$8,$I$8,IF(NEGRO!C11=$E$9,$I$9,$I$10)),$J$8,E30,". ") -> Actualmente, el nivel del Río Negro está en ascenso en la ciudad de Mercedes. | J30: =_xlfn.CONCAT(F13,IF(NEGRO!C16>NEGRO!C7,I13, IF(NEGRO!C16=NEGRO!C7,I14, I15))) -> Considerando las lluvias pronosticadas y los niveles registrados en las estaciones de monitoreo, existe la posibilidad de nuevos incrementos de nivel en los próximos días. | K30: =IF(NEGRO!C9="-","",IF(NEGRO!C16>NEGRO!C9,_xlfn.CONCAT(F18,NEGRO!C9,I18),_xlfn.CONCAT(F19,NEGRO!C9,I19))) | L30: =+_xlfn.CONCAT(F30," ",I30, " ",J30," ",K30) -> #REF!

Sheet log
A1: Fecha | B1: Responsable | C1: Cambios | D1: Comentarios
A2: 45224 | B2: F. Hastings | C2: Se agregó un campo "nivel pico anterior en CIUDAD" para los casos de tormentas con varios picos, en el capo se debe ingresar el nivel del pico maximo anterior de la tormenta. | D2: Este campo falta agregarlo al Scrript de pyton.
A3: 45224 | B3: F. Hastings | C3: El campo "Recomendación al SINAE" se estandarizó a partir de una lista que se encuentra en la hoja "Tablas". Se puede seleccionar una opción y luego editarla. La lista se puede editar para incorporar o eliminar opciones.
A4: 45224 | B4: F. Hastings | C4: El campo "Pronóstico hidrológico" se estandarizó considerando los datos ingresados de precipitaciones y niveles. | D4: Para la cuenca del río Uruguay donde se informan cuatro ciudades, si la tendencia no es la misma hay que arreglar manualmente la frase agregando comas o "y" que separan los nombres de las ciudades según corresponda.
A5: 45224 | B5: F. Hastings | C5: Se agregó una hoja "Tablas" donde se encuentran las opciones de listas y hay tablas auxiliares para estandarizar la redaccion de los campos.
A6: 45224 | B6: F. Hastings | D6: pronos_CIUDAD debe ser un campo numerico para que funcione la automatización del campo "Pronóstico hidrológico"
A7: 45224 | B7: F. Hastings | C7: Se cambiaron las fórmulas de los campos "tasa de incremento (cm/hora)" y "tendencia (sube, baja o permanece)". | D7: Si la tendencia es a la baja no se calcula la tasa.
